<?xml version="1.0" encoding="utf-8"?>
<robot name="jaka_mobile" xmlns:xacro="http://www.ros.org/wiki/xacro">

    <xacro:include filename="./zu7.urdf.xacro" />

    <xacro:macro name="jaka_base" params="base_link:='base'">
        <link name="world"/>
        <link name="x_link">
            <inertial>
                <origin xyz="0 0 0" rpy="0 0 0" />
                <mass value="3.06"/>
                <inertia ixx="0.3" ixy="0.0" ixz="0.0" iyy="0.3" iyz="0.0" izz="0.3" />
            </inertial>
        </link>

        <joint name="x_base_joint" type="prismatic">
            <origin rpy="0 0 0" xyz="0 0 0"/>
            <axis xyz="1 0 0"/>
            <parent link="world"/>
            <child link="x_link"/>
            <limit lower="-10" upper="10" effort="200" velocity="2"/>
        </joint>

        <link name="y_link">
            <inertial>
                <origin xyz="0 0 0" rpy="0 0 0" />
                <mass value="3.06"/>
                <inertia ixx="0.3" ixy="0.0" ixz="0.0" iyy="0.3" iyz="0.0" izz="0.3" />
            </inertial>
        </link>

        <joint name="y_base_joint" type="prismatic">
            <origin rpy="0 0 0" xyz="0 0 0"/>
            <axis xyz="0 1 0"/>
            <parent link="x_link"/>
            <child link="y_link"/>
            <limit lower="-10" upper="10" effort="200" velocity="2"/>
        </joint>

        <joint name="w_base_joint" type="revolute">
            <origin rpy="0 0 0" xyz="0 0 0.218"/>
            <axis xyz="0 0 1"/>
            <parent link="y_link"/>
            <child link="${base_link}"/>
            <limit effort="200" velocity="2" upper="30" lower="-30"/>
        </joint>

        <link name="${base_link}">
            <collision>
                <!-- <origin xyz="0 0 0" rpy="0 0 0"/>
                <geometry>
                    <box size="0.5 0.5 0.25"/>
                </geometry> -->
                <origin xyz="0 0 -0.2" rpy="0 0 0" />
                <geometry>
                <mesh filename="package://mppi_ros/resources/mesh/agv_zu7/collision/agv.stl" scale="1 1 1" />
                </geometry>   
            </collision>
            <visual>
                <origin xyz="0 0 -0.2" rpy="0 0 0" />
                <geometry>
                <mesh filename="package://mppi_ros/resources/mesh/agv_zu7/visual/agv_sjtu.dae" scale="1 1 1" />
                </geometry>
                <material name="">
                <color rgba="0.84706 0.84706 0.84706 1"/>
                </material>            
            </visual>
        </link>

        <joint name="base_wheel" type="fixed">
            <origin rpy="0 0 0" xyz="0 0 0"/>
            <axis xyz="0 0 1"/>
            <parent link="${base_link}"/>
            <child link="wheel_link"/>
        </joint>

        <link name="wheel_link">
            <collision>
                <origin xyz="-0.345 -0.32 -0.2" rpy="0 0 0" />
                <!-- <origin xyz="-0.345 0.32 0" rpy="1.5709 0 0" /> -->
                <geometry>
                <mesh filename="package://mppi_ros/resources/mesh/agv_zu7/visual/wheels.dae" scale="1 1 1" />
                </geometry>            
            </collision>
            <visual>
                <origin xyz="-0.345 -0.32 -0.2" rpy="0 0 0" />
                <!-- <origin xyz="-0.345 0.32 0" rpy="1.5709 0 0" /> -->
                <geometry>
                <mesh filename="package://mppi_ros/resources/mesh/agv_zu7/visual/wheels.dae" scale="1 1 1" />
                </geometry>
                <material name="">
                <color rgba="0.84706 0.84706 0.84706 1"/>
                </material>             
            </visual>
        </link>
    </xacro:macro>

    <xacro:jaka_base base_link="base"/>

    <xacro:zu7_robot  prefix="jaka_"
                        q1="0.0"
                        q2="0.0"
                        q3="0.0"
                        q4="0.0"
                        q5="0.0"
                        q6="0.0"
                        source ="mppi_ros"/>
                        
    <joint name="mobile_jaka_joint" type="fixed">
        <parent link="base"/>
        <child link="jaka_base_link"/>
        <origin xyz="0.1395 0 0.1965" rpy="0 0 0"/>
    </joint>

</robot>
